Workbook
Name harga_bahan: 'HARGA SATUAN'!$D$5:$I$2650
Name hsp: HSP!$B$9:$I$847

Sheet HARGA SATUAN
B2: HARGA UPAH, BAHAN, DAN PERALATAN
B3: TAHUN ANGGARAN 2026
B5: No | C5: Uraian | E5: Kode | F5: Sat. | G5: Harga (Rp) | H5: Ket. | I5: TKDN
B6: Column1 | C6: Column2 | D6: Column3 | E6: Column4 | F6: Column5 | G6: Column6 | H6: Column7 | I6: Column8 | J6: Column9 | K6: Column10
B7: A. | C7: UPAH TENAGA SESUAI UMP DAERAH | K7: ,..,
K8: ,..,
B9: 1 | D9: Pekerja | E9: L.01 | F9: OH | G9: 160105.2 | H9: SK GUGERNUR NO. 404 TAHUN 2025 TENTANG PENETAPAN UMP SULUT 2026 | I9: 1 | K9: ,..,
K10: ,..,
B11: B. | C11: UPAH TENAGA SESUAI HARGA PERUSAHAAN | K11: ,..,
K12: ,..,
B13: 2 | D13: Tukang Batu | E13: L.02a | F13: OH | G13: 185000 | H13: HARGA SURVEY | I13: 1 | K13: ,..,
B14: 3 | D14: Tukang Kayu | E14: L.02b | F14: OH | G14: 185000 | H14: HARGA SURVEY | I14: 1 | K14: ,..,
B15: 4 | D15: Tukang Besi | E15: L.02c | F15: OH | G15: 185000 | H15: HARGA SURVEY | I15: 1 | K15: ,..,
B16: 5 | D16: Tukang Beton | E16: L.02d | F16: OH | G16: 185000 | H16: HARGA SURVEY | I16: 1 | K16: ,..,
B17: 6 | D17: Tukang Pipa | E17: L.02e | F17: OH | G17: 185000 | H17: HARGA SURVEY | I17: 1 | K17: ,..,
B18: 7 | D18: Tukang las | E18: L.02f | F18: OH | G18: 250000 | H18: HARGA SURVEY | I18: 1 | K18: ,..,
B19: 8 | D19: Tukang Listrik | E19: L.02g | F19: OH | G19: 250000 | H19: HARGA SURVEY | I19: 1 | K19: ,..,
B20: 9 | D20: Tukang Kaca | E20: L.02h | F20: OH | G20: 185000 | H20: HARGA SURVEY | I20: 1 | K20: ,..,
B21: 10 | D21: Tukang Alumunium | E21: L.02i | F21: OH | G21: 185000 | H21: HARGA SURVEY | I21: 1 | K21: ,..,
B22: 11 | D22: Tukang Cat | E22: L.02j | F22: OH | G22: 185000 | H22: HARGA SURVEY | I22: 1 | K22: ,..,
B23: 12 | D23: Tukang Tanaman | E23: L.02k | F23: OH | G23: 185000 | H23: HARGA SURVEY | I23: 1 | K23: ,..,
B24: 13 | D24: Kepala tukang | E24: L.03 | F24: OH | G24: 200000 | H24: HARGA SURVEY | I24: 1 | K24: ,..,
... B33: 22 | D33: Pembantu Supir | E33: L.11 | F33: OH | G33: 100000 | H33: HARGA SURVEY | I33: 1 | K33: ,..,
B35: C. | C35: BAHAN LOKAL | K35: ,..,
B36: 1 | C36: Batu | K36: ,..,
C37: - | D37: Batu Kali/ Batu Sungai | E37: A.1.1 | F37: m3 | G37: 250000 | H37: HARGA SURVEY | I37: 0.97 | K37: ,..,
C38: - | D38: Kerikil Sungai | E38: A.1.2 | F38: m3 | G38: 240000 | H38: HARGA SURVEY | K38: ,..,
C39: - | D39: Batu Gunung | E39: A.1.3 | F39: m3 | G39: 225000 | H39: HARGA SHST 2025 | K39: ,..,
C40: - | D40: Batu Belah 15 - 20 cm | E40: A.1.4 | F40: m3 | G40: 225000 | H40: HARGA SHST 2025 | I40: 0.99 | K40: ,..,
C41: - | D41: Batu Belah 5 - 7 cm | E41: A.1.5 | F41: m3 | G41: 225000 | H41: HARGA SHST 2025 | K41: ,..,
C42: - | D42: Batu Split @30-50 mm | E42: A.1.6 | F42: m3 | G42: 450000 | H42: HARGA SURVEY | I42: 0.97 | K42: ,..,
C43: - | D43: Batu Split @20-30 mm | E43: A.1.7 | F43: m3 | G43: 500000 | H43: HARGA SURVEY | I43: 0.91 | K43: ,..,
C44: - | D44: Batu Split @20-30 mm | E44: A.1.8 | F44: Kg | G44: 370.37037 | H44: HARGA SURVEY | I44: 0.91 | K44: ,..,
C45: - | D45: Batu Split @10-20 mm | E45: A.1.9 | F45: m3 | G45: 500000 | H45: HARGA SURVEY | I45: 0.92 | K45: ,..,
C46: - | D46: Batu Split 0-5 mm (Abu Batu) | E46: A.1.10 | F46: m3 | G46: 333333 | H46: HARGA SHST 2025 | K46: ,..,
C47: - | D47: Bata Merah @12 | E47: A.1.11 | F47: Buah | G47: 1100 | H47: HARGA SURVEY | I47: 0.94 | K47: ,..,
C48: - | D48: Bata Merah @9 | E48: A.1.12 | F48: Buah | G48: 550 | H48: HARGA SHST 2025 | K48: ,..,
C49: - | D49: Batako @40 cm x 20 cm x 20 cm x 10 cm | E49: A.1.15 | F49: Buah | G49: 6000 | H49: HARGA SURVEY | I49: 0.98 | K49: ,..,
C50: - | D50: Pas. Bata 1:3 | E50: A.1.16 | F50: m2 | G50: 377306.47 | H50: HARGA SURVEY | I50: 0.92 | K50: ,..,
G51: 0 | K51: ,..,
...

Sheet HSP
B3: HSP (HARGA SATUAN PEKERJAAN)
B4: Surat Edaran Direktur Jenderal Bina Konstruksi Nomor 182/SE/Dk/2025
B6: Kode AHSP-CK 2025 | C6: Kode AHSP-Umum | D6: Uraian | E6: Ket. | F6: Sat. | G6: TKDN | H6: Harga Satuan Jadi | I6: Harga Satuan Jadi
H7: elevasi 0 - 400 cm (LT 1) | I7: elevasi 401 - 800 cm (LT 2)
B8: Column1 | C8: Column2 | D8: Column3 | E8: Column4 | F8: Column5 | G8: Column6 | H8: Column7 | I8: Column8
B9: 1 | C9: PERSIAPAN LAPANGAN / SITE WORK
B10: 1.1 | C10: PEKERJAAN PERSIAPAN
B11: 1.1.1 | C11: PEMBUATAN PAGAR PROYEK
B12: 1.1.1.1 | D12: Pembuatan 1 m’ pagar sementara dari kayu tinggi 2 meter | F12: m' | G12: 0.97230769 | H12: 549164.42
B13: 1.1.1.2 | D13: Pembuatan 1 m’ pagar sementara dari seng gelombang rangka kayu tinggi 2 meter | F13: m' | G13: 0.97083333 | H13: 417554.26
B14: 1.1.1.3 | D14: Pembuatan 1 m’ pagar sementara dari kawat duri tinggi 2 meter | F14: m' | G14: 0.97 | H14: 429544.08
B15: 1.1.1.4 | D15: Pembuatan 1 m’ pagar sementara seng gelombang rangka baja L.40.40.4 tinggi pagar 1.8 meter | F15: m' | G15: 0.97375 | H15: 539923.06
B16: 1.1.1.5 | D16: Pembuatan 1 m2 pagar BRC Galvanis | F16: m2 | G16: 1 | H16: 21982.858
B17: 1.1.2 | C17: ALAT DAN/ATAU SARANA PENUNJANG
B18: 1.1.2.1 | D18: 1 buah papan nama pekerjaan ukuran 0.8x1.2 menggunakan multiflex 18 mm, frame besi siku dan tiang kayu 8/12 | F18: bh | G18: 0.977 | H18: 1409158.3
B19: 1.1.3 | C19: Pembersihan dan Pengupasan Permukaan Tanah
B20: 1.1.3.1 | D20: 1 m3 Pembersihan dan pengupasan permukaan tanah (striping) s.d. tanaman ∅ 2 cm | F20: m3 | G20: 1 | H20: 19849.598
B21: 1.1.3.2 | D21: Tebas tebang 1 m2 tanaman/tumbuhan ∅ < 5 cm | F21: m2 | G21: 1 | H21: 6386.1294
B22: 1.1.3.3 | D22: Tebas tebang 1 m 2 tanaman/tumbuhan ∅ >5 s.d. 15 cm | F22: m2 | G22: 1 | H22: 10643.549
B23: 1.1.4 | C23: Pembersihan dan Pengupasan Permukaan Tanah
B24: 1.1.4.2 | D24: Pasangan 1 m' bouwplank | F24: m' | G24: 0.98375 | H24: 62894.952
B25: 1.1.4.3 | D25: Patok Kayu (kaso5/7) Panjang 0,5 m' | F25: m' | G25: 0.98142857 | H25: 48760.968
B26: 1.1.4.4 | D26: 1 Buah Patok Kayu (Kaso 5/7) panjang 1 m' | F26: m' | G26: 0.98142857 | H26: 55201.452
B27: 1.2 | C27: PEKERJAAN GALIAN TANAH
B28: 1.2.1 | C28: TANAH BIASA
B29: 1.2.1.1 | C29: Cara Manual
B30: 1.2.1.1.1 | D30: Penggalian 1 m3 tanah biasa sedalam 0 s.d. 1 m untuk volume s.d. 200 m3 secara manual | F30: m3 | G30: 1 | H30: 149015.73
B31: 1.2.1.1.2 | D31: Penggalian 1 m3 tanah biasa sedalam 0 s.d. 1 m untuk volume 200 m3 s.d 2.000 m3 secara manual | F31: m3 | G31: 1 | H31: 119846.36
B32: 1.2.1.1.3 | D32: Penggalian 1 m3 tanah biasa sedalam 0 s.d. 1 m untuk volume > 2.000 m3 secara Manual | F32: m3 | G32: 1 | H32: 85148.392
B33: 1.2.1.1.4 | D33: Penggalian 1 m3 tanah biasa sedalam > 1 s.d. 2 m untuk volume s.d 200 m3 secara manual | F33: m3 | G33: 1 | H33: 178646.38
B34: 1.2.1.1.5 | D34: Penggalian 1 m3 tanah biasa sedalam > 1 s.d. 2 m untuk volume > 200 m3 secara manual | F34: m3 | G34: 1 | H34: 143687.91
B35: 1.2.1.1.6 | D35: Penggalian 1 m3 tanah biasa sedalam > 2 s.d. 3 m untuk volume s.d 200 m3 secara manual | F35: m3 | G35: 1 | H35: 212589.53
B36: 1.2.1.1.7 | D36: Penggalian 1 m3 tanah biasa sedalam > 2 s.d. 3 m untuk volume > 200 m3 secara manual | F36: m3 | G36: 1 | H36: 161781.94
B37: 1.2.1.1.8 | D37: Penggalian 1 m3 tanah biasa sedalam > 3 m, setiap penambahan kedalaman 1 m secara manual | F37: m3 | G37: 1 | H37: 15965.324
B38: 1.2.1.2 | C38: Cara Semi Mekanis
B39: 1.2.1.2.1 | D39: Penggalian 1 m3 tanh biasa sedalam > 0 s.d 1 m secara semi mekanis | F39: m3 | G39: 0.99333333 | H39: 49556.741
B40: 1.2.1.2.2 | D40: Penggalian 1 m3 tanah biasa sedalam >1 s.d 2 m secara semi mekanis | F40: m3 | G40: 0.99333333 | H40: 61764.199
B41: 1.2.1.2.3 | D41: Penggalian 1 m3 tanah biasa sedalam >2 s.d 3 m secara semi mekanis | F41: m3 | G41: 0.99333333 | H41: 76350.144
B42: 1.2.1.2.4 | D42: Penggalian 1 m3 tanah biasa > 3 m untuk setiap penambahan kedalaman 1 m secara semi mekanis | F42: m3 | G42: 0.99333333 | H42: 17353.267
B43: 1.2.2 | C43: PASIR
...

Sheet AHSP
B3: AHSP (ANALISA HARGA SATUAN PEKERJAAN)
B5: Surat Edaran Direktur Jenderal Bina Konstruksi Nomor 182/SE/Dk/2025
B7: NO | C7: URAIAN | E7: KODE | F7: SAT. | G7: KOEF. | H7: HARGA SATUAN | I7: UPAH (Rp) | J7: BAHAN (Rp) | K7: ALAT (Rp) | L7: PROFIT | M7: TOTAL (Rp) | N7: TKDN
B8: Column1 | C8: Column2 | D8: Column3 | E8: Column4 | F8: Column5 | G8: Column6 | H8: Column7 | I8: Column8 | J8: Column9 | K8: Column10 | L8: Column11 | M8: Column12 | N8: Column13 | O8: Column14 | P8: Column15
B9: 1 | C9: PERSIAPAN LAPANGAN / SITE WORK | P9: ,..,
B10: 1.1 | C10: PEKERJAAN PERSIAPAN | P10: ,..,
B11: 1.1.1 | C11: PEMBUATAN PAGAR PROYEK | P11: ,..,
B12: 1.1.1.1 | D12: Pembuatan 1 m’ pagar sementara dari kayu tinggi 2 meter | F12: m' | I12: 181313.12 | J12: 296221.16 | K12: 0 | L12: 0.15 | M12: 549164.42 | N12: 0.97230769 | P12: ,..,
D13: Pekerja | E13: L.01 | F13: OH | G13: 0.6 | H13: 160105.2 | I13: 96063.12 | N13: 1 | P13: ,..,
D14: Tukang kayu | E14: L.02b | F14: OH | G14: 0.2 | H14: 185000 | I14: 37000 | N14: 1 | P14: ,..,
D15: Tukang batu | E15: L.02a | F15: OH | G15: 0.2 | H15: 185000 | I15: 37000 | N15: 1 | P15: ,..,
D16: Kepala tukang | E16: L.03 | F16: OH | G16: 0.04 | H16: 200000 | I16: 8000 | N16: 1 | P16: ,..,
D17: Mandor | E17: L.04 | F17: OH | G17: 0.013 | H17: 250000 | I17: 3250 | N17: 1 | P17: ,..,
D18: Kaso 5/7 kayu kelas II | E18: A.7.9 | F18: m3 | G18: 0.0387 | H18: 2500000 | J18: 96750 | N18: 1 | P18: ,..,
D19: Papan Kayu ukuran 2/20 cm | E19: A.7.5 | F19: m3 | G19: 0.0396 | H19: 2500000 | J19: 99000 | N19: 0.97 | P19: ,..,
D20: Paku biasa 5 inchi | E20: B.9.2 | F20: kg | G20: 0.5872 | H20: 18000 | J20: 10569.6 | N20: 0.96 | P20: ,..,
D21: Semen Portland (PC) | E21: B.1.2 | F21: kg | G21: 26.406 | H21: 1310 | J21: 34591.86 | N21: 0.96 | P21: ,..,
D22: Pasir Beton | E22: A.4.2 | F22: kg | G22: 61.56 | H22: 357.14286 | J22: 21985.714 | N22: 0.93 | P22: ,..,
D23: Kerikil (kg) | E23: A.1.7 | F23: kg | G23: 83.349 | H23: 370.37037 | J23: 30870 | N23: 0.91 | P23: ,..,
D24: Air | E24: A.8.1 | F24: liter | G24: 17.415 | H24: 3.1 | J24: 53.9865 | N24: 0.94 | P24: ,..,
D25: Residu | E25: B.4.20 | F25: liter | G25: 0.4 | H25: 6000 | J25: 2400 | N25: 0.97 | P25: ,..,
D26: (Lihat Permen PUPR Nomor 8 Tahun 2023 Lampiran B U.1.1.1 (c)) | P26: ,..,
B27: 1.1.1.2 | D27: Pembuatan 1 m’ pagar sementara dari seng gelombang rangka kayu tinggi 2 meter | F27: m' | I27: 93276.3 | J27: 269814.36 | K27: 0 | L27: 0.15 | M27: 417554.26 | N27: 0.97083333 | P27: ,..,
D28: Pekerja | E28: L.01 | F28: OH | G28: 0.25 | H28: 160105.2 | I28: 40026.3 | N28: 1 | P28: ,..,
D29: Tukang kayu | E29: L.02b | F29: OH | G29: 0.125 | H29: 185000 | I29: 23125 | N29: 1 | P29: ,..,
D30: Tukang batu | E30: L.02a | F30: OH | G30: 0.125 | H30: 185000 | I30: 23125 | N30: 1 | P30: ,..,
D31: Kepala tukang | E31: L.03 | F31: OH | G31: 0.025 | H31: 200000 | I31: 5000 | N31: 1 | P31: ,..,
D32: Mandor | E32: L.04 | F32: OH | G32: 0.008 | H32: 250000 | I32: 2000 | N32: 1 | P32: ,..,
D33: Kaso 5/7 kayu kelas II | E33: A.7.9 | F33: m3 | G33: 0.031 | H33: 2500000 | J33: 77500 | N33: 1 | P33: ,..,
D34: Seng gelombang | E34: B.2.4 | F34: lembar | G34: 1.3125 | H34: 74000 | J34: 97125 | N34: 0.95 | P34: ,..,
D35: Paku biasa 5 inchi | E35: B.9.2 | F35: kg | G35: 0.4271 | H35: 18000 | J35: 7687.8 | N35: 0.96 | P35: ,..,
D36: Semen Portland (PC) | E36: B.1.2 | F36: kg | G36: 26.406 | H36: 1310 | J36: 34591.86 | N36: 0.96 | P36: ,..,
D37: Pasir Beton | E37: A.4.2 | F37: kg | G37: 61.56 | H37: 357.14286 | J37: 21985.714 | N37: 0.93 | P37: ,..,
D38: Kerikil (kg) | E38: A.1.7 | F38: kg | G38: 83.349 | H38: 370.37037 | J38: 30870 | N38: 0.91 | P38: ,..,
D39: Air | E39: A.8.1 | F39: liter | G39: 17.415 | H39: 3.1 | J39: 53.9865 | N39: 0.94 | P39: ,..,
D40: (Lihat Permen PUPR Nomor 8 Tahun 2023 Lampiran B U.1.1.2 (c)) | P40: ,..,
B41: 1.1.1.3 | D41: Pembuatan 1 m’ pagar sementara dari kawat duri tinggi 2 meter | F41: m' | I41: 114992.4 | J41: 258524.19 | K41: 0 | L41: 0.15 | M41: 429544.08 | N41: 0.97 | P41: ,..,
D42: Pekerja | E42: L.01 | F42: OH | G42: 0.308 | H42: 160105.2 | I42: 49312.402 | N42: 1 | P42: ,..,
D43: Tukang kayu | E43: L.02b | F43: OH | G43: 0.154 | H43: 185000 | I43: 28490 | N43: 1 | P43: ,..,
D44: Tukang batu | E44: L.02a | F44: OH | G44: 0.154 | H44: 185000 | I44: 28490 | N44: 1 | P44: ,..,
...

Sheet RAB_PEMBUATAN SANITASI
B2: Rencana Anggaran Biaya (RAB)
B4: PROGRAM | D4: : | E4: -
B5: KEGIATAN | D5: : | E5: PEMBUATAN SANITASI
B6: SUB. KEGIATAN | D6: : | E6: -
B7: PEKERJAAN | D7: : | E7: PEKERJAAN PEMBUATAN SANITASI
B8: LOKASI | D8: : | E8: KOTA KOTAMOBAGU
B9: TAHUN ANGGARAN | D9: : | E9: 2026
B11: NO | C11: JENIS PEKERJAAN | F11: SAT | G11: VOL | H11: HARGA SATUAN (Rp) | I11: JUMLAH HARGA (Rp) | J11: NILAI TKDN (%) | K11: JUMLAH HARGA TKDN (Rp)
B12: Column1 | C12: Column2 | E12: Column3 | F12: Column4 | G12: Column5 | H12: Column6 | I12: Column7 | J12: Column8 | K12: Column9 | L12: Column14 | M12: Column15
B13: 1 | C13: 2 | F13: 3 | G13: 4 | H13: 5 | I13: 6 | J13: 7 | K13: 8 | M13: ,..,
B14: A | C14: PEKERJAAN PERSIAPAN | M14: ,.., | N14: =IFERROR(IF(P14="","",_xlfn.XLOOKUP(P14, HSP!D:D, HSP!B:B)),"")
B15: 1 | C15: Papan Nama Kegiatan | G15: 1 | H15: 200000 | I15: =IFERROR($G15*$H15,"") -> 200000 | M15: ,.., | N15: =IFERROR(IF(P15="","",_xlfn.XLOOKUP(P15, HSP!D:D, HSP!B:B)),"") | P15: Papan Nama Kegiatan
M16: ,.., | N16: =IFERROR(IF(P16="","",_xlfn.XLOOKUP(P16, HSP!D:D, HSP!B:B)),"")
B17: B | C17: PEKERJAAN PERLENGKAPAN K3 | M17: ,.., | N17: =IFERROR(IF(P17="","",_xlfn.XLOOKUP(P17, HSP!D:D, HSP!B:B)),"")
B18: 1 | C18: Pengadaan Spanduk | G18: 1 | H18: 200000 | I18: =IFERROR($G18*$H18,"") -> 200000 | M18: ,.., | N18: =IFERROR(IF(P18="","",_xlfn.XLOOKUP(P18, HSP!D:D, HSP!B:B)),"") | P18: Pengadaan Spanduk K3
B19: 2 | C19: Pengadaan Helm Safety | G19: 3 | H19: 50000 | I19: =IFERROR($G19*$H19,"") -> 150000 | M19: ,.., | N19: =IFERROR(IF(P19="","",_xlfn.XLOOKUP(P19, HSP!D:D, HSP!B:B)),"") | P19: Pengadaan Helm Safety
B20: 3 | C20: Pengadaan Rompi Safety | G20: 3 | H20: 50000 | I20: =IFERROR($G20*$H20,"") -> 150000 | M20: ,.., | N20: =IFERROR(IF(P20="","",_xlfn.XLOOKUP(P20, HSP!D:D, HSP!B:B)),"") | P20: Pengadaan Rompi Safety
B21: 4 | C21: Pengadaan Sepatu Boots | G21: 3 | H21: 120000 | I21: =IFERROR($G21*$H21,"") -> 360000 | M21: ,.., | N21: =IFERROR(IF(P21="","",_xlfn.XLOOKUP(P21, HSP!D:D, HSP!B:B)),"") | P21: Pengadaan Sepatu Boots
B22: 1 | C22: 1 | M22: ,.., | N22: =IFERROR(IF(P22="","",_xlfn.XLOOKUP(P22, HSP!D:D, HSP!B:B)),"")
B23: C | C23: PEKERJAAN TANKI SEPTIK INDIVIDUAL | M23: ,.., | N23: =IFERROR(IF(P23="","",_xlfn.XLOOKUP(P23, HSP!D:D, HSP!B:B)),"")
B24: 1 | C24: Dinding Batu Bata | F24: =IFERROR(VLOOKUP($N24,hsp,5,0),"") -> m3 | G24: 5.275 | H24: =IFERROR(VLOOKUP($N24,hsp,7,0),"") -> 143687.91 | I24: =IFERROR($G24*$H24,"") -> 757953.73 | M24: ,.., | N24: =IFERROR(IF(P24="","",_xlfn.XLOOKUP(P24, HSP!D:D, HSP!B:B)),"") -> 1.2.1.1.5 | P24: Penggalian 1 m3 tanah biasa sedalam > 1 s.d. 2 m untuk volume > 200 m3 secara manual
B25: 2 | C25: Plesteran | F25: =IFERROR(VLOOKUP($N25,hsp,5,0),"") -> m3 | G25: 0.1625 | H25: =IFERROR(VLOOKUP($N25,hsp,7,0),"") -> 266836.61 | I25: =IFERROR($G25*$H25,"") -> 43360.95 | M25: ,.., | N25: =IFERROR(IF(P25="","",_xlfn.XLOOKUP(P25, HSP!D:D, HSP!B:B)),"") -> 1.3.1.3 | P25: 1 m3 urukan pasir uruk untuk volume > 200 m3 tanpa pemadatan secara manual
B26: 3 | C26: Acian | F26: =IFERROR(VLOOKUP($N26,hsp,5,0),"") -> m3 | G26: 0.7775 | H26: =IFERROR(VLOOKUP($N26,hsp,7,0),"") -> 266836.61 | I26: =IFERROR($G26*$H26,"") -> 207465.47 | M26: ,.., | N26: =IFERROR(IF(P26="","",_xlfn.XLOOKUP(P26, HSP!D:D, HSP!B:B)),"") -> 1.3.1.3 | P26: 1 m3 urukan pasir uruk untuk volume > 200 m3 tanpa pemadatan secara manual
B27: 4 | C27: Pengecetan Exterior | F27: =IFERROR(VLOOKUP($N27,hsp,5,0),"") -> m3 | G27: 0.1625 | H27: =IFERROR(VLOOKUP($N27,hsp,7,0),"") -> 1622459.3 | I27: =IFERROR($G27*$H27,"") -> 263649.64 | M27: ,.., | N27: =IFERROR(IF(P27="","",_xlfn.XLOOKUP(P27, HSP!D:D, HSP!B:B)),"") -> 2.2.1.4.4 | P27: 1 m3 beton mutu rendah f'c 17 MPa, slump (100 ± 25) mm, agregat maks 19 mm secara manual
B28: 5 | C28: Dinding Batu Bata | F28: =IFERROR(VLOOKUP($N28,hsp,5,0),"") -> m2 | G28: 9.4075 | H28: =IFERROR(VLOOKUP($N28,hsp,7,0),"") -> 178282.02 | I28: =IFERROR($G28*$H28,"") -> 1677188.1 | M28: ,.., | N28: =IFERROR(IF(P28="","",_xlfn.XLOOKUP(P28, HSP!D:D, HSP!B:B)),"") -> 3.6.1.9 | P28: Pemasangan 1 m2 dinding bata merah tebal 1/2 batu dengan mortar tipe O,fc’ 2,4 MPa (Setara Campuran 1SP : 5PP)
B29: 6 | C29: Plesteran | F29: =IFERROR(VLOOKUP($N29,hsp,5,0),"") -> m3 | G29: 0.09 | H29: =IFERROR(VLOOKUP($N29,hsp,7,0),"") -> 1622459.3 | I29: =IFERROR($G29*$H29,"") -> 146021.34 | M29: ,.., | N29: =IFERROR(IF(P29="","",_xlfn.XLOOKUP(P29, HSP!D:D, HSP!B:B)),"") -> 2.2.1.4.4 | P29: 1 m3 beton mutu rendah f'c 17 MPa, slump (100 ± 25) mm, agregat maks 19 mm secara manual
B30: 7 | C30: Cor Sloof Beton | F30: =IFERROR(VLOOKUP($N30,hsp,5,0),"") -> m3 | G30: 0.045 | H30: =IFERROR(VLOOKUP($N30,hsp,7,0),"") -> 1622459.3 | I30: =IFERROR($G30*$H30,"") -> 73010.67 | M30: ,.., | N30: =IFERROR(IF(P30="","",_xlfn.XLOOKUP(P30, HSP!D:D, HSP!B:B)),"") -> 2.2.1.4.4 | P30: 1 m3 beton mutu rendah f'c 17 MPa, slump (100 ± 25) mm, agregat maks 19 mm secara manual
B31: 8 | C31: Cor Kolom Beton | F31: =IFERROR(VLOOKUP($N31,hsp,5,0),"") -> m3 | G31: 0.35 | H31: =IFERROR(VLOOKUP($N31,hsp,7,0),"") -> 1622459.3 | I31: =IFERROR($G31*$H31,"") -> 567860.76 | M31: ,.., | N31: =IFERROR(IF(P31="","",_xlfn.XLOOKUP(P31, HSP!D:D, HSP!B:B)),"") -> 2.2.1.4.4 | P31: 1 m3 beton mutu rendah f'c 17 MPa, slump (100 ± 25) mm, agregat maks 19 mm secara manual
B32: 9 | C32: Tanki Septic Prabrikasi | F32: Unit | G32: 1 | H32: 4700000 | I32: =IFERROR($G32*$H32,"") -> 4700000 | M32: ,.., | N32: =IFERROR(IF(P32="","",_xlfn.XLOOKUP(P32, HSP!D:D, HSP!B:B)),"") | P32: Tanki Septic Prabrikasi
M33: ,.., | N33: =IFERROR(IF(P33="","",_xlfn.XLOOKUP(P33, HSP!D:D, HSP!B:B)),"")
B34: D | C34: PEKERJAAN JARINGAN PIPA | M34: ,.., | N34: =IFERROR(IF(P34="","",_xlfn.XLOOKUP(P34, HSP!D:D, HSP!B:B)),"")
B35: 1 | C35: Galian tanah | F35: m' | G35: 0.72 | H35: 143687.91 | I35: =IFERROR($G35*$H35,"") -> 103455.3 | M35: ,.., | N35: =IFERROR(IF(P35="","",_xlfn.XLOOKUP(P35, HSP!D:D, HSP!B:B)),"") -> 1.2.1.1.5 | P35: Penggalian 1 m3 tanah biasa sedalam > 1 s.d. 2 m untuk volume > 200 m3 secara manual
B36: 2 | C36: Pemasangan Pipa PVC 4" | F36: m' | G36: 3 | H36: 146185.63 | I36: =IFERROR($G36*$H36,"") -> 438556.89 | M36: ,.., | N36: =IFERROR(IF(P36="","",_xlfn.XLOOKUP(P36, HSP!D:D, HSP!B:B)),"") -> 6.4.1.22 | P36: Pemasangan 1 m pipa PVC D, DN. 4" (100 mm)
B37: 3 | C37: Pemasangan Pipa PVC 1" Ventilasi | F37: m' | G37: 2 | H37: 62981.743 | I37: =IFERROR($G37*$H37,"") -> 125963.49 | M37: ,.., | N37: =IFERROR(IF(P37="","",_xlfn.XLOOKUP(P37, HSP!D:D, HSP!B:B)),"") -> 5.5.4.13 | P37: Pemasangan 1 m' pipa PVC AW, DN. 1" (25 mm) + Isolasi
B38: 4 | C38: Urugan Tanah Kembali | F38: m' | G38: 0.18 | H38: 99247.99 | I38: =IFERROR($G38*$H38,"") -> 17864.638 | M38: ,.., | N38: =IFERROR(IF(P38="","",_xlfn.XLOOKUP(P38, HSP!D:D, HSP!B:B)),"") -> 1.3.1.1 | P38: 1 m3 urukan kembali galian tanah ( >0 s.d 200 m3) tanpa pemadatan secara manual
B39: 5 | C39: Pemasangan Pipa PVC 2" | F39: m' | G39: 1 | H39: 60724.049 | I39: =IFERROR($G39*$H39,"") -> 60724.049 | M39: ,.., | N39: =IFERROR(IF(P39="","",_xlfn.XLOOKUP(P39, HSP!D:D, HSP!B:B)),"") -> 9.1.1.22 | P39: Pemasangan 1 m Pipa PVC, DN. 2" (50 mm)
B40: 6 | C40: Aksesoris Pipa | F40: Bh | G40: 2 | H40: 25000 | I40: =IFERROR($G40*$H40,"") -> 50000 | M40: ,.., | N40: =IFERROR(IF(P40="","",_xlfn.XLOOKUP(P40, HSP!D:D, HSP!B:B)),"") | P40: Aksesoris Pipa PVC
M41: ,.., | N41: =IFERROR(IF(P41="","",_xlfn.XLOOKUP(P41, HSP!D:D, HSP!B:B)),"")
B42: E | C42: PEKERJAAN RESAPAN | M42: ,.., | N42: =IFERROR(IF(P42="","",_xlfn.XLOOKUP(P42, HSP!D:D, HSP!B:B)),"")
B43: 1 | C43: Galian Tanah | F43: m' | G43: 0.5125 | H43: 143687.91 | I43: =IFERROR($G43*$H43,"") -> 73640.055 | M43: ,.., | N43: =IFERROR(IF(P43="","",_xlfn.XLOOKUP(P43, HSP!D:D, HSP!B:B)),"") -> 1.2.1.1.5 | P43: Penggalian 1 m3 tanah biasa sedalam > 1 s.d. 2 m untuk volume > 200 m3 secara manual
...
